Watching for file changes with StatReloader
"GET /base-info/users_wallet/?username=st2257 HTTP/1.1" 200 40
"GET /base-info/building/?institute=%D0%9C%D0%A4%D0%A2%D0%98 HTTP/1.1" 200 751
"GET /base-info/audience/?institute=%D0%9C%D0%A4%D0%A2%D0%98&status=%D0%A1%D0%B2%D0%BE%D0%B1%D0%BE%D0%B4%D0%BD%D0%BE HTTP/1.1" 200 4437
"GET /base-info/users_wallet/?username=st2257 HTTP/1.1" 200 40
"GET /base-info/history/?user=st2257 HTTP/1.1" 200 16066
"GET /base-info/book/?user=st2257 HTTP/1.1" 200 2
"GET /base-info/users_wallet/?username=st2257 HTTP/1.1" 200 40
"GET /base-info/history/?user=st2257 HTTP/1.1" 200 16066
"GET /base-info/book/?user=st2257 HTTP/1.1" 200 2
/usr/src/app/backend/settings.py changed, reloading.
Watching for file changes with StatReloader
/usr/src/app/backend/settings.py changed, reloading.
Watching for file changes with StatReloader
/usr/src/app/backend/settings.py changed, reloading.
Watching for file changes with StatReloader
"GET /base-info/users_wallet/?username=st2257 HTTP/1.1" 200 40
"GET /base-info/building/?institute=%D0%9C%D0%A4%D0%A2%D0%98 HTTP/1.1" 200 751
"GET /base-info/audience/?institute=%D0%9C%D0%A4%D0%A2%D0%98&status=%D0%A1%D0%B2%D0%BE%D0%B1%D0%BE%D0%B4%D0%BD%D0%BE HTTP/1.1" 200 4437
"GET /base-info/users_wallet/?username=st2257 HTTP/1.1" 200 40
"GET /base-info/users_wallet/?username=st2257 HTTP/1.1" 200 40
"GET /base-info/users_wallet/?username=st2257 HTTP/1.1" 200 40
"GET /base-info/history/?user=st2257 HTTP/1.1" 200 16066
"GET /base-info/book/?user=st2257 HTTP/1.1" 200 2
"GET /base-info/users_wallet/?username=st2257 HTTP/1.1" 200 40
"GET /base-info/audience/?institute=%D0%9C%D0%A4%D0%A2%D0%98 HTTP/1.1" 200 5779
"GET /base-info/users_wallet/?username=st2257 HTTP/1.1" 200 40
"GET /base-info/history/?user=st2257 HTTP/1.1" 200 16066
"GET /base-info/book/?user=st2257 HTTP/1.1" 200 2
"GET /base-info/users_wallet/?username=st2257 HTTP/1.1" 200 40
"GET /base-info/audience/?institute=%D0%9C%D0%A4%D0%A2%D0%98 HTTP/1.1" 200 5779
"GET /base-info/users_wallet/?username=st2257 HTTP/1.1" 200 40
"GET /base-info/building/?institute=%D0%9C%D0%A4%D0%A2%D0%98 HTTP/1.1" 200 751
"GET /base-info/audience/?institute=%D0%9C%D0%A4%D0%A2%D0%98&status=%D0%A1%D0%B2%D0%BE%D0%B1%D0%BE%D0%B4%D0%BD%D0%BE HTTP/1.1" 200 4437
"GET /base-info/users_wallet/?username=st2257 HTTP/1.1" 200 40
"GET /base-info/users_wallet/?username=st2257 HTTP/1.1" 200 40
"GET /base-info/users_wallet/?username=st2257 HTTP/1.1" 200 40
"GET /base-info/history/?user=st2257 HTTP/1.1" 200 16066
"GET /base-info/book/?user=st2257 HTTP/1.1" 200 2
Retrying (Retry(total=4, connect=None, read=None, redirect=None, status=None)) after connection broken by 'NewConnectionError('<urllib3.connection.HTTPSConnection object at 0x7f5c81b906d0>: Failed to establish a new connection: [Errno 111] Connection refused')': /get-info/
Retrying (Retry(total=3, connect=None, read=None, redirect=None, status=None)) after connection broken by 'NewConnectionError('<urllib3.connection.HTTPSConnection object at 0x7f5c81b79710>: Failed to establish a new connection: [Errno 111] Connection refused')': /get-info/
Retrying (Retry(total=2, connect=None, read=None, redirect=None, status=None)) after connection broken by 'NewConnectionError('<urllib3.connection.HTTPSConnection object at 0x7f5c82d25350>: Failed to establish a new connection: [Errno 111] Connection refused')': /get-info/
"GET /base-info/users_wallet/?username=st2257 HTTP/1.1" 200 40
"GET /base-info/audience/?institute=%D0%9C%D0%A4%D0%A2%D0%98 HTTP/1.1" 200 5779
"GET /base-info/users_wallet/?username=st2257 HTTP/1.1" 200 40
"GET /base-info/history/?user=st2257 HTTP/1.1" 200 16066
"GET /base-info/book/?user=st2257 HTTP/1.1" 200 2
"GET /base-info/users_wallet/?username=st2257 HTTP/1.1" 200 40
"GET /base-info/users_wallet/?username=st2257 HTTP/1.1" 200 40
Retrying (Retry(total=1, connect=None, read=None, redirect=None, status=None)) after connection broken by 'NewConnectionError('<urllib3.connection.HTTPSConnection object at 0x7f5c82d24850>: Failed to establish a new connection: [Errno 111] Connection refused')': /get-info/
"OPTIONS /base-info/users_wallet/?username=null HTTP/1.1" 200 0
"OPTIONS /base-info/users_wallet/?username=null HTTP/1.1" 200 0
"GET /base-info/users_wallet/?username=null HTTP/1.1" 200 2
"GET /base-info/users_wallet/?username=null HTTP/1.1" 200 2
"GET /base-info/users_wallet/?username=st2257 HTTP/1.1" 200 40
"GET /base-info/users_wallet/?username=st2257 HTTP/1.1" 200 40
"GET /base-info/users_wallet/?username=st2257 HTTP/1.1" 200 40
"GET /base-info/building/?institute=%D0%9C%D0%A4%D0%A2%D0%98 HTTP/1.1" 200 751
"GET /base-info/audience/?institute=%D0%9C%D0%A4%D0%A2%D0%98&status=%D0%A1%D0%B2%D0%BE%D0%B1%D0%BE%D0%B4%D0%BD%D0%BE HTTP/1.1" 200 4437
"GET /base-info/users_wallet/?username=st2257 HTTP/1.1" 200 40
"GET /base-info/users_wallet/?username=st2257 HTTP/1.1" 200 40
Retrying (Retry(total=0, connect=None, read=None, redirect=None, status=None)) after connection broken by 'NewConnectionError('<urllib3.connection.HTTPSConnection object at 0x7f5c81c23e50>: Failed to establish a new connection: [Errno 111] Connection refused')': /get-info/
"GET /base-info/users_wallet/?username=st2257 HTTP/1.1" 200 40
"GET /base-info/audience/?institute=%D0%9C%D0%A4%D0%A2%D0%98 HTTP/1.1" 200 5779
Internal Server Error: /book/
Traceback (most recent call last):
  File "/usr/local/lib/python3.11/site-packages/urllib3/connection.py", line 174, in _new_conn
    conn = connection.create_connection(
           ^^^^^^^^^^^^^^^^^^^^^^^^^^^^^
  File "/usr/local/lib/python3.11/site-packages/urllib3/util/connection.py", line 95, in create_connection
    raise err
  File "/usr/local/lib/python3.11/site-packages/urllib3/util/connection.py", line 85, in create_connection
    sock.connect(sa)
ConnectionRefusedError: [Errno 111] Connection refused

During handling of the above exception, another exception occurred:

Traceback (most recent call last):
  File "/usr/local/lib/python3.11/site-packages/urllib3/connectionpool.py", line 715, in urlopen
    httplib_response = self._make_request(
                       ^^^^^^^^^^^^^^^^^^^
  File "/usr/local/lib/python3.11/site-packages/urllib3/connectionpool.py", line 404, in _make_request
    self._validate_conn(conn)
  File "/usr/local/lib/python3.11/site-packages/urllib3/connectionpool.py", line 1060, in _validate_conn
    conn.connect()
  File "/usr/local/lib/python3.11/site-packages/urllib3/connection.py", line 363, in connect
    self.sock = conn = self._new_conn()
                       ^^^^^^^^^^^^^^^^
  File "/usr/local/lib/python3.11/site-packages/urllib3/connection.py", line 186, in _new_conn
    raise NewConnectionError(
urllib3.exceptions.NewConnectionError: <urllib3.connection.HTTPSConnection object at 0x7f5c82d5d750>: Failed to establish a new connection: [Errno 111] Connection refused

During handling of the above exception, another exception occurred:

Traceback (most recent call last):
  File "/usr/local/lib/python3.11/site-packages/requests/adapters.py", line 667, in send
    resp = conn.urlopen(
           ^^^^^^^^^^^^^
  File "/usr/local/lib/python3.11/site-packages/urllib3/connectionpool.py", line 829, in urlopen
    return self.urlopen(
           ^^^^^^^^^^^^^
  File "/usr/local/lib/python3.11/site-packages/urllib3/connectionpool.py", line 829, in urlopen
    return self.urlopen(
           ^^^^^^^^^^^^^
  File "/usr/local/lib/python3.11/site-packages/urllib3/connectionpool.py", line 829, in urlopen
    return self.urlopen(
           ^^^^^^^^^^^^^
  [Previous line repeated 2 more times]
  File "/usr/local/lib/python3.11/site-packages/urllib3/connectionpool.py", line 801, in urlopen
    retries = retries.increment(
              ^^^^^^^^^^^^^^^^^^
  File "/usr/local/lib/python3.11/site-packages/urllib3/util/retry.py", line 594, in increment
    raise MaxRetryError(_pool, url, error or ResponseError(cause))
urllib3.exceptions.MaxRetryError: HTTPSConnectionPool(host='mipt.site', port=8088): Max retries exceeded with url: /get-info/ (Caused by NewConnectionError('<urllib3.connection.HTTPSConnection object at 0x7f5c82d5d750>: Failed to establish a new connection: [Errno 111] Connection refused'))

During handling of the above exception, another exception occurred:

Traceback (most recent call last):
  File "/usr/local/lib/python3.11/site-packages/django/core/handlers/exception.py", line 55, in inner
    response = get_response(request)
               ^^^^^^^^^^^^^^^^^^^^^
  File "/usr/local/lib/python3.11/site-packages/django/core/handlers/base.py", line 197, in _get_response
    response = wrapped_callback(request, *callback_args, **callback_kwargs)
               ^^^^^^^^^^^^^^^^^^^^^^^^^^^^^^^^^^^^^^^^^^^^^^^^^^^^^^^^^^^^
  File "/usr/local/lib/python3.11/site-packages/django/views/decorators/csrf.py", line 54, in wrapped_view
    return view_func(*args, **kwargs)
           ^^^^^^^^^^^^^^^^^^^^^^^^^^
  File "/usr/local/lib/python3.11/site-packages/django/views/decorators/csrf.py", line 54, in wrapped_view
    return view_func(*args, **kwargs)
           ^^^^^^^^^^^^^^^^^^^^^^^^^^
  File "/usr/local/lib/python3.11/site-packages/django/views/generic/base.py", line 103, in view
    return self.dispatch(request, *args, **kwargs)
           ^^^^^^^^^^^^^^^^^^^^^^^^^^^^^^^^^^^^^^^
  File "/usr/local/lib/python3.11/site-packages/rest_framework/views.py", line 509, in dispatch
    response = self.handle_exception(exc)
               ^^^^^^^^^^^^^^^^^^^^^^^^^^
  File "/usr/local/lib/python3.11/site-packages/rest_framework/views.py", line 469, in handle_exception
    self.raise_uncaught_exception(exc)
  File "/usr/local/lib/python3.11/site-packages/rest_framework/views.py", line 480, in raise_uncaught_exception
    raise exc
  File "/usr/local/lib/python3.11/site-packages/rest_framework/views.py", line 506, in dispatch
    response = handler(request, *args, **kwargs)
               ^^^^^^^^^^^^^^^^^^^^^^^^^^^^^^^^^
  File "/usr/local/lib/python3.11/site-packages/rest_framework/decorators.py", line 50, in handler
    return func(*args, **kwargs)
           ^^^^^^^^^^^^^^^^^^^^^
  File "/usr/src/app/main/views.py", line 166, in book_audience
    check_token_result = asyncio.run(check_token(token))
                         ^^^^^^^^^^^^^^^^^^^^^^^^^^^^^^^
  File "/usr/local/lib/python3.11/asyncio/runners.py", line 190, in run
    return runner.run(main)
           ^^^^^^^^^^^^^^^^
  File "/usr/local/lib/python3.11/asyncio/runners.py", line 118, in run
    return self._loop.run_until_complete(task)
           ^^^^^^^^^^^^^^^^^^^^^^^^^^^^^^^^^^^
  File "/usr/local/lib/python3.11/asyncio/base_events.py", line 653, in run_until_complete
    return future.result()
           ^^^^^^^^^^^^^^^
  File "/usr/src/app/main/services.py", line 37, in check_token
    res = await asyncio.gather(response)
          ^^^^^^^^^^^^^^^^^^^^^^^^^^^^^^
  File "/usr/src/app/main/services.py", line 25, in make_auth_request
    response = session.get(
               ^^^^^^^^^^^^
  File "/usr/local/lib/python3.11/site-packages/requests/sessions.py", line 602, in get
    return self.request("GET", url, **kwargs)
           ^^^^^^^^^^^^^^^^^^^^^^^^^^^^^^^^^^
  File "/usr/local/lib/python3.11/site-packages/requests/sessions.py", line 589, in request
    resp = self.send(prep, **send_kwargs)
           ^^^^^^^^^^^^^^^^^^^^^^^^^^^^^^
  File "/usr/local/lib/python3.11/site-packages/requests/sessions.py", line 703, in send
    r = adapter.send(request, **kwargs)
        ^^^^^^^^^^^^^^^^^^^^^^^^^^^^^^^
  File "/usr/local/lib/python3.11/site-packages/requests/adapters.py", line 700, in send
    raise ConnectionError(e, request=request)
requests.exceptions.ConnectionError: HTTPSConnectionPool(host='mipt.site', port=8088): Max retries exceeded with url: /get-info/ (Caused by NewConnectionError('<urllib3.connection.HTTPSConnection object at 0x7f5c82d5d750>: Failed to establish a new connection: [Errno 111] Connection refused'))
"POST /book/ HTTP/1.1" 500 244599
"GET /base-info/users_wallet/?username=st2257 HTTP/1.1" 200 40
"GET /base-info/history/?user=st2257 HTTP/1.1" 200 16066
"GET /base-info/book/?user=st2257 HTTP/1.1" 200 2
"GET /base-info/users_wallet/?username=st2257 HTTP/1.1" 200 40
"GET /base-info/users_wallet/?username=st2257 HTTP/1.1" 200 40
"GET /base-info/users_wallet/?username=st2257 HTTP/1.1" 200 40
"GET /base-info/building/?institute=%D0%9C%D0%A4%D0%A2%D0%98 HTTP/1.1" 200 751
"GET /base-info/audience/?institute=%D0%9C%D0%A4%D0%A2%D0%98&status=%D0%A1%D0%B2%D0%BE%D0%B1%D0%BE%D0%B4%D0%BD%D0%BE HTTP/1.1" 200 4437
Retrying (Retry(total=4, connect=None, read=None, redirect=None, status=None)) after connection broken by 'NewConnectionError('<urllib3.connection.HTTPSConnection object at 0x7f5c82d6a390>: Failed to establish a new connection: [Errno 111] Connection refused')': /get-info/
Retrying (Retry(total=3, connect=None, read=None, redirect=None, status=None)) after connection broken by 'NewConnectionError('<urllib3.connection.HTTPSConnection object at 0x7f5c82d27790>: Failed to establish a new connection: [Errno 111] Connection refused')': /get-info/
Retrying (Retry(total=2, connect=None, read=None, redirect=None, status=None)) after connection broken by 'NewConnectionError('<urllib3.connection.HTTPSConnection object at 0x7f5c81b7c2d0>: Failed to establish a new connection: [Errno 111] Connection refused')': /get-info/
